<?xml version="1.0" ?>

<!-- adapted from Daniel Mellinger, Nathan Michael, Vijay Kumar, "Trajectory Generation and Control for Precise Aggressive Maneuvers with Quadrotors" -->

<robot xmlns="http://drake.mit.edu"
 xmlns:xsi="http://www.w3.org/2001/XMLSchema-instance"
 xsi:schemaLocation="http://drake.mit.edu ../../../../pods/drake/doc/drakeURDF.xsd" name="quadrotor">
  
  <link name="base_link">
    <!-- Visual Representation -->
    <inertial>
      <origin xyz="0 0 -0.1" rpy="0 0 0"/> <!-- Adjust as needed -->
      <mass value="10.0"/> <!-- Tether mass -->
      <inertia ixx="0.0001" ixy="0" ixz="0" iyy="0.0001" iyz="0" izz="0.0001"/> <!-- Simplified inertia -->
    </inertial>
    <visual>
      <geometry>
        <box size="0.2 0.2 0.1"/> <!-- Cube dimensions: length, width, height in meters -->
      </geometry>
      <material name="blue">
        <color rgba="0 0 1 1"/> <!-- Color: Blue -->
      </material>
    </visual>
    <collision>
      <geometry>
        <box size="0.2 0.2 0.1"/>
      </geometry>
    </collision>
  </link>


  <!-- Tether Model -->

  <!-- Tether Link 1 -->
  <link name="tether_seg_1">
    <inertial>
      <origin xyz="0 0 -0.1" rpy="0 0 0"/> <!-- Adjust as needed -->
      <mass value="0.01"/> <!-- Tether mass -->
      <inertia ixx="0.1" ixy="0" ixz="0" iyy="0.1" iyz="0" izz="0.1"/> <!-- Simplified inertia -->
    </inertial>
    <visual>
      <origin xyz="0 0 -0.1" rpy="0 0 0"/> <!-- Center of the cylinder -->
      <geometry>
        <cylinder radius="0.01" length="0.2"/> <!-- Tether dimensions -->
      </geometry>
    </visual>
    <collision>
      <origin xyz="0 0 -0.1" rpy="0 0 0"/>
      <geometry>
        <cylinder radius="0.01" length="0.2"/>
      </geometry>
    </collision>
  </link>

  <!-- Joint connecting tether to drone -->
  <joint name="tether_joint_1" type="fixed">
    <parent link="base_link"/>
    <child link="tether_seg_1"/>
    <origin xyz="0 0 -0.05" rpy="0 0 0"/> <!-- Adjust as needed -->
  </joint>

  <link name="tether_seg_2">
    <inertial>
      <origin xyz="0 0 -0.1" rpy="0 0 0"/> <!-- Adjust as needed -->
      <mass value="0.01"/> <!-- Tether mass -->
      <inertia ixx="0.1" ixy="0" ixz="0" iyy="0.1" iyz="0" izz="0.1"/> <!-- Simplified inertia -->
    </inertial>
    <visual>
      <origin xyz="0 0 -0.1" rpy="0 0 0"/> <!-- Center of the cylinder -->
      <geometry>
        <cylinder radius="0.01" length="0.2"/> <!-- Tether dimensions -->
      </geometry>
    </visual>
    <collision>
      <origin xyz="0 0 -0.15" rpy="0 0 0"/>
      <geometry>
        <cylinder radius="0.01" length="0.2"/>
      </geometry>
    </collision>
  </link>

  <joint name="tether_joint_2" type="continuous">
    <parent link="tether_seg_1"/>
    <child link="tether_seg_2"/>
    <origin xyz="0 0 -0.3" rpy="0 0 0"/>
    <limit effort="1000.0" lower="-3.14" upper="3.14" velocity="500.0"/>
		<axis xyz = "1 0 0" />
    <dynamics damping="0.000005" friction="0.000001"/>
  </joint>
  
</robot>